<?xml version="1.0" ?>
<mujoco model="franka_panda v200">
    <!-- =================================================
    Copyright 2018 Vikash Kumar
    Model   :: Franka (MuJoCoV2.0)
    Author  :: Vikash Kumar (vikashplus@gmail.com)
    source  :: https://github.com/vikashplus/franka_sim
    License :: Under Apache License, Version 2.0 (the "License"); you may not use this file except in compliance with the License. You may obtain a copy of the License at http://www.apache.org/licenses/LICENSE-2.0 Unless required by applicable law or agreed to in writing, software distributed under the License is distributed on an "AS IS" BASIS, WITHOUT WARRANTIES OR CONDITIONS OF ANY KIND, either express or implied. See the License for the specific language governing permissions and limitations under the License.
====================================================== -->
    <compiler angle="radian"/>
    <size nconmax="100" njmax="500" nuser_actuator="5"/>
    <default class="main">
        <default class="panda">
            <joint limited="true"/>
            <general biasprm="0 -1 0 0 0 0 0 0 0 0" biastype="affine" ctrllimited="true" forcelimited="true" user="1002 40 2001 -0.005 0.005"/>
            <default class="panda_viz">
                <geom conaffinity="0" contype="0" rgba="0.95 0.99 0.92 1" type="mesh"/>
                <general user="1002 40 2001 -0.005 0.005"/>
            </default>
            <default class="panda_col">
                <geom group="3" rgba="0.5 0.6 0.7 1" type="mesh"/>
                <general user="1002 40 2001 -0.005 0.005"/>
            </default>
            <default class="panda_arm">
                <joint damping="0.1"/>
                <general user="1002 40 2001 -0.005 0.005"/>
            </default>
            <default class="panda_forearm">
                <joint damping="0.01"/>
                <general user="1002 40 2001 -0.005 0.005"/>
            </default>
            <default class="panda_finger">
                <joint armature="5" damping="100"/>
                <geom conaffinity="0" condim="6" friction="1 0.5 0.0001" group="3" margin="0.001" rgba="0.5 0.6 0.7 0.4" solimp="0.8 0.9 0.001 0.5 2" solref="0.01 1"/>
                <general user="1002 40 2001 -0.0001 0.0001"/>
            </default>
        </default>
        <default class="panda_overlay">
            <joint armature="1" damping="1000" frictionloss="10"/>
            <geom conaffinity="0" contype="0" group="2" rgba="0.42 0.42 0.42 0.5" type="mesh"/>
        </default>
    </default>
    <asset>
        <texture builtin="checker" height="512" name="texplane" rgb1="0.2 0.3 0.4" rgb2="0.1 0.15 0.2" type="2d" width="512"/>
        <material name="MatGnd" reflectance="0.5" texture="texplane" texuniform="true"/>
        <mesh file="./meshes/collision/link0.stl" name="link0_col"/>
        <mesh file="./meshes/collision/link1.stl" name="link1_col"/>
        <mesh file="./meshes/collision/link2.stl" name="link2_col"/>
        <mesh file="./meshes/collision/link3.stl" name="link3_col"/>
        <mesh file="./meshes/collision/link4.stl" name="link4_col"/>
        <mesh file="./meshes/collision/link5.stl" name="link5_col"/>
        <mesh file="./meshes/collision/link6.stl" name="link6_col"/>
        <mesh file="./meshes/collision/link7.stl" name="link7_col"/>
        <mesh file="./meshes/collision/hand.stl" name="hand_col"/>
        <mesh file="./meshes/visual/link0.stl" name="link0_viz"/>
        <mesh file="./meshes/visual/link1.stl" name="link1_viz"/>
        <mesh file="./meshes/visual/link2.stl" name="link2_viz"/>
        <mesh file="./meshes/visual/link3.stl" name="link3_viz"/>
        <mesh file="./meshes/visual/link4.stl" name="link4_viz"/>
        <mesh file="./meshes/visual/link5.stl" name="link5_viz"/>
        <mesh file="./meshes/visual/link6.stl" name="link6_viz"/>
        <mesh file="./meshes/visual/link7.stl" name="link7_viz"/>
        <mesh file="./meshes/visual/hand.stl" name="hand_viz"/>
        <mesh file="./meshes/collision/finger.stl" name="finger_col" scale="1.75 1 1.75"/>
        <mesh file="./meshes/collision/finger.stl" name="finger_viz" scale="1.75 1 1.75"/>
    </asset>
    <worldbody>
        <geom material="MatGnd" name="ground" size="5 5 10" type="plane"/>
        <light diffuse="0.8 0.8 0.8" dir="-0.301511 -0.301511 -0.904534" pos="1 1 3"/>
        <light diffuse="0.8 0.8 0.8" dir="-0.301511 0.301511 -0.904534" pos="1 -1 3"/>
        <light diffuse="0.8 0.8 0.8" dir="0.316228 0 -0.948683" pos="-1 0 3"/>
        <body childclass="panda" name="panda0_link0" pos="0 0 0">
            <inertial diaginertia="0.122527 0.11364 0.0827785" mass="2.91242" pos="0 0 0"/>
            <geom class="panda_viz" mesh="link0_viz"/>
            <geom class="panda_col" mesh="link0_col"/>
            <body name="panda0_link1" pos="0 0 0.333">
                <inertial diaginertia="0.70337 0.70661 0.009117" mass="4.970684" pos="0.003875 0.002081 0"/>
                <joint axis="0 0 1" class="panda_arm" name="panda0_joint1" pos="0 0 0" range="-2.8973 2.8973"/>
                <geom class="panda_viz" mesh="link1_viz"/>
                <geom class="panda_col" mesh="link1_col"/>
                <body name="panda0_link2" pos="0 0 0" quat="0.707107 -0.707107 0 0">
                    <inertial diaginertia="0.007962 0.02811 0.025995" mass="0.646926" pos="-3.141e-03 -2.872e-02 3.495e-03"/>
                    <joint axis="0 0 1" class="panda_arm" name="panda0_joint2" pos="0 0 0" range="-1.7628 1.7628"/>
                    <geom class="panda_viz" mesh="link2_viz"/>
                    <geom class="panda_col" mesh="link2_col"/>
                    <body name="panda0_link3" pos="0 -0.316 0" quat="0.707107 0.707107 0 0">
                        <inertial diaginertia="0.037242 0.036155 0.01083" mass="3.228604" pos="2.7518e-02 3.9252e-02 -6.6502e-02"/>
                        <joint axis="0 0 1" class="panda_arm" name="panda0_joint3" pos="0 0 0" range="-2.8973 2.8973"/>
                        <geom class="panda_viz" mesh="link3_viz"/>
                        <geom class="panda_col" mesh="link3_col"/>
                        <body name="panda0_link4" pos="0.0825 0 0" quat="0.707107 0.707107 0 0">
                            <inertial diaginertia="0.025853 0.019552 0.028323" mass="3.587895" pos="-5.317e-02 1.04419e-01 2.7454e-02"/>
                            <joint axis="0 0 1" class="panda_arm" name="panda0_joint4" pos="0 0 0" range="-3.0718 -0.4"/>
                            <geom class="panda_viz" mesh="link4_viz"/>
                            <geom class="panda_col" mesh="link4_col"/>
                            <body name="panda0_link5" pos="-0.0825 0.384 0" quat="0.707107 -0.707107 0 0">
                                <inertial diaginertia="0.035549 0.029474 0.008627" mass="1.225946" pos="-1.1953e-02 4.1065e-02 -3.8437e-02"/>
                                <joint axis="0 0 1" class="panda_forearm" name="panda0_joint5" pos="0 0 0" range="-2.8973 2.8973"/>
                                <geom class="panda_viz" mesh="link5_viz"/>
                                <geom class="panda_col" mesh="link5_col"/>
                                <body name="panda0_link6" pos="0 0 0" quat="0.707107 0.707107 0 0">
                                    <inertial diaginertia="0.001964 0.004354 0.005433" mass="1.666555" pos="6.0149e-02 -1.4117e-02 -1.0517e-02"/>
                                    <joint axis="0 0 1" class="panda_forearm" name="panda0_joint6" pos="0 0 0" range="-1.6573 2.1127"/>
                                    <geom class="panda_viz" mesh="link6_viz"/>
                                    <geom class="panda_col" mesh="link6_col"/>
                                    <body name="panda0_link7" pos="0.088 0 0" quat="0.707107 0.707107 0 0">
                                        <inertial diaginertia="0.012516 0.010027 0.004815" mass="7.35522e-01" pos="1.0517e-02 -4.252e-03 6.1597e-02"/>
                                        <joint axis="0 0 1" class="panda_forearm" name="panda0_joint7" pos="0 0 0" range="-2.8973 2.8973"/>
                                        <geom class="panda_viz" mesh="link7_viz"/>
                                        <geom class="panda_col" mesh="link7_col"/>
                                    </body>
                                </body>
                            </body>
                        </body>
                    </body>
                </body>
            </body>
        </body>
    </worldbody>
    <actuator>
        <general ctrllimited="true" ctrlrange="-80 80" joint="panda0_joint1" name="panda0_joint1"/>
        <general ctrllimited="true" ctrlrange="-80 80" joint="panda0_joint2" name="panda0_joint2"/>
        <general ctrllimited="true" ctrlrange="-80 80" joint="panda0_joint3" name="panda0_joint3"/>
        <general ctrllimited="true" ctrlrange="-80 80" joint="panda0_joint4" name="panda0_joint4"/>
        <general ctrllimited="true" ctrlrange="-80 80" joint="panda0_joint5" name="panda0_joint5"/>
        <general ctrllimited="true" ctrlrange="-12 12" joint="panda0_joint6" name="panda0_joint6"/>
        <general ctrllimited="true" ctrlrange="-12 12" joint="panda0_joint7" name="panda0_joint7"/>
    </actuator>
    <sensor>
        <jointpos joint="panda0_joint1" name="fr_arm_jp1"/>
        <jointpos joint="panda0_joint2" name="fr_arm_jp2"/>
        <jointpos joint="panda0_joint3" name="fr_arm_jp3"/>
        <jointpos joint="panda0_joint4" name="fr_arm_jp4"/>
        <jointpos joint="panda0_joint5" name="fr_arm_jp5"/>
        <jointpos joint="panda0_joint6" name="fr_arm_jp6"/>
        <jointpos joint="panda0_joint7" name="fr_arm_jp7"/>
        <jointvel joint="panda0_joint1" name="fr_arm_jv1"/>
        <jointvel joint="panda0_joint2" name="fr_arm_jv2"/>
        <jointvel joint="panda0_joint3" name="fr_arm_jv3"/>
        <jointvel joint="panda0_joint4" name="fr_arm_jv4"/>
        <jointvel joint="panda0_joint5" name="fr_arm_jv5"/>
        <jointvel joint="panda0_joint6" name="fr_arm_jv6"/>
        <jointvel joint="panda0_joint7" name="fr_arm_jv7"/>
        <actuatorfrc actuator="panda0_joint1" name="fr_arm_jf1"/>
        <actuatorfrc actuator="panda0_joint2" name="fr_arm_jf2"/>
        <actuatorfrc actuator="panda0_joint3" name="fr_arm_jf3"/>
        <actuatorfrc actuator="panda0_joint4" name="fr_arm_jf4"/>
        <actuatorfrc actuator="panda0_joint5" name="fr_arm_jf5"/>
        <actuatorfrc actuator="panda0_joint6" name="fr_arm_jf6"/>
        <actuatorfrc actuator="panda0_joint7" name="fr_arm_jf7"/>
    </sensor>
    <keyframe>
        <key qpos="0.0 0.0 0.0 0.0 0.0 0.0 0.0" qvel="0.0 0.0 0.0 0.0 0.0 0.0 0.0" time="0.0"/>
    </keyframe>
</mujoco>
